<mujoco model="right_allegro_hand scene">
  <include file="allegro_right_hand_revert_palm_tip_collision.xml" />

  <statistic center="0 0 0" extent="0.3" />

  <visual>
    <rgba haze="0.15 0.25 0.35 1" />
    <quality shadowsize="8192" />
    <global azimuth="130" elevation="-40" offwidth="1280" offheight="960" />
  </visual>

  <asset>
    <texture name="surface" file="../assets/textures/general_block.png" gridsize="3 4" gridlayout=".U..LFRB.D.." />
    <material name="obj_material" texture="surface" specular="1" shininess="0.3" reflectance="0.4" />

    <texture type="2d" name="groundplane" builtin="checker" mark="edge" rgb1="0.2 0.3 0.4" rgb2="0.1 0.2 0.3" markrgb="0.8 0.8 0.8" width="300" height="300" />
    <material name="groundplane" texture="groundplane" texuniform="true" texrepeat="5 5" reflectance="0." />
  </asset>

  <worldbody>
    <light directional="true" ambient="0.4 0.4 0.4" diffuse="1.0 1.0 1.0" castshadow="false" pos="0 1 4" dir="0 0 -1" name="light0" />
    <camera name="demo-cam" pos="-0.012 -0.297 0.363" xyaxes="1.000 -0.002 0.000 0.001 0.674 0.739" />

    <geom name="floor" pos="0 0 -0.1" size="0 0 0.05" type="plane" material="groundplane" />

    <body name="goal" pos="0.035 0.0 0.25" euler="0 0 0">
      <body name="goal_axis">
        <geom name="goal" type="sphere" size="0.06" rgba="0.1 0.5 0.5 0.8" conaffinity="0" contype="0" pos="0.0 0.0 0.0" quat="1 0 0 0" />
        <geom type="cylinder" pos="0.0 0.0 0.0325" size="0.005 0.035" rgba="0.0 0.0 1.0 1.0" class="visual" />
        <geom type="cylinder" pos="0.0 0.0325 0.0" euler="1.5708 0.0 0.0" size="0.005 0.035" rgba="0.0 1.0 0.0 1.0" class="visual" />
        <geom type="cylinder" pos="0.0325 0.0 0.0" euler="0.0 1.5708 0.0" size="0.005 0.035" rgba="1.0 0.0 0.0 1.0" class="visual" />
      </body>
    </body>
    
    <body name="object" pos="0.035 0.0 0.072" euler="0 0 0">
      <inertial pos="0 0 0" mass="0.1" diaginertia="0.000144 0.000144 0.000144" />
      <geom name="object_geom" type="sphere" size="0.054" rgba="0.1 0.5 0.5 0.8" condim="6" priority="1" friction="2.0 0.002 0.002" margin="0.04" gap="0.04" />
      <geom type="cylinder" pos="0.0 0.0 0.0325" size="0.005 0.035" rgba="0.0 0.0 1.0 1.0" class="visual" />
      <geom type="cylinder" pos="0.0 0.0325 0.0" euler="1.5708 0.0 0.0" size="0.005 0.035" rgba="0.0 1.0 0.0 1.0" class="visual" />
      <geom type="cylinder" pos="0.0325 0.0 0.0" euler="0.0 1.5708 0.0" size="0.005 0.035" rgba="1.0 0.0 0.0 1.0" class="visual" />
      <joint type="ball" axis="0 0 1" damping="0.1" />
    </body>
  </worldbody>
</mujoco>